[2024-05-24T12:14:02.144+0000] {local_task_job_runner.py:120} INFO - ::group::Pre task execution logs
[2024-05-24T12:14:02.152+0000] {taskinstance.py:2076} INFO - Dependencies all met for dep_context=non-requeueable deps ti=<TaskInstance: train_and_deploy_model.train_model manual__2024-05-24T12:14:01.279170+00:00 [queued]>
[2024-05-24T12:14:02.155+0000] {taskinstance.py:2076} INFO - Dependencies all met for dep_context=requeueable deps ti=<TaskInstance: train_and_deploy_model.train_model manual__2024-05-24T12:14:01.279170+00:00 [queued]>
[2024-05-24T12:14:02.155+0000] {taskinstance.py:2306} INFO - Starting attempt 1 of 2
[2024-05-24T12:14:02.160+0000] {taskinstance.py:2330} INFO - Executing <Task(PythonOperator): train_model> on 2024-05-24 12:14:01.279170+00:00
[2024-05-24T12:14:02.162+0000] {warnings.py:110} WARNING - /home/***/.local/lib/python3.12/site-packages/***/task/task_runner/standard_task_runner.py:61: DeprecationWarning: This process (pid=59) is multi-threaded, use of fork() may lead to deadlocks in the child.
  pid = os.fork()

[2024-05-24T12:14:02.163+0000] {standard_task_runner.py:90} INFO - Running: ['***', 'tasks', 'run', 'train_and_deploy_model', 'train_model', 'manual__2024-05-24T12:14:01.279170+00:00', '--job-id', '717', '--raw', '--subdir', 'DAGS_FOLDER/train_and_deploy_dag.py', '--cfg-path', '/tmp/tmp4uqe1a9m']
[2024-05-24T12:14:02.164+0000] {standard_task_runner.py:63} INFO - Started process 60 to run task
[2024-05-24T12:14:02.164+0000] {standard_task_runner.py:91} INFO - Job 717: Subtask train_model
[2024-05-24T12:14:02.180+0000] {task_command.py:426} INFO - Running <TaskInstance: train_and_deploy_model.train_model manual__2024-05-24T12:14:01.279170+00:00 [running]> on host b2ab95bd73fd
[2024-05-24T12:14:02.206+0000] {taskinstance.py:2648} INFO - Exporting env vars: AIRFLOW_CTX_DAG_OWNER='***' AIRFLOW_CTX_DAG_ID='train_and_deploy_model' AIRFLOW_CTX_TASK_ID='train_model' AIRFLOW_CTX_EXECUTION_DATE='2024-05-24T12:14:01.279170+00:00' AIRFLOW_CTX_TRY_NUMBER='1' AIRFLOW_CTX_DAG_RUN_ID='manual__2024-05-24T12:14:01.279170+00:00'
[2024-05-24T12:14:02.207+0000] {taskinstance.py:430} INFO - ::endgroup::
[2024-05-24T12:14:02.244+0000] {taskinstance.py:441} INFO - ::group::Post task execution logs
[2024-05-24T12:14:02.244+0000] {taskinstance.py:2905} ERROR - Task failed with exception
Traceback (most recent call last):
  File "/home/airflow/.local/lib/python3.12/site-packages/airflow/models/taskinstance.py", line 465, in _execute_task
    result = _execute_callable(context=context, **execute_callable_kwargs)
             ^^^^^^^^^^^^^^^^^^^^^^^^^^^^^^^^^^^^^^^^^^^^^^^^^^^^^^^^^^^^^
  File "/home/airflow/.local/lib/python3.12/site-packages/airflow/models/taskinstance.py", line 432, in _execute_callable
    return execute_callable(context=context, **execute_callable_kwargs)
           ^^^^^^^^^^^^^^^^^^^^^^^^^^^^^^^^^^^^^^^^^^^^^^^^^^^^^^^^^^^^
  File "/home/airflow/.local/lib/python3.12/site-packages/airflow/models/baseoperator.py", line 400, in wrapper
    return func(self, *args, **kwargs)
           ^^^^^^^^^^^^^^^^^^^^^^^^^^^
  File "/home/airflow/.local/lib/python3.12/site-packages/airflow/operators/python.py", line 235, in execute
    return_value = self.execute_callable()
                   ^^^^^^^^^^^^^^^^^^^^^^^
  File "/home/airflow/.local/lib/python3.12/site-packages/airflow/operators/python.py", line 252, in execute_callable
    return self.python_callable(*self.op_args, **self.op_kwargs)
           ^^^^^^^^^^^^^^^^^^^^^^^^^^^^^^^^^^^^^^^^^^^^^^^^^^^^^
  File "/opt/airflow/dags/train_and_deploy_dag.py", line 26, in train_model
    raise Exception(f"Training script failed: {result.stderr}")
Exception: Training script failed: python: can't open file '/opt/***/../train_model.py': [Errno 2] No such file or directory

[2024-05-24T12:14:02.249+0000] {taskinstance.py:1206} INFO - Marking task as UP_FOR_RETRY. dag_id=train_and_deploy_model, task_id=train_model, run_id=manual__2024-05-24T12:14:01.279170+00:00, execution_date=20240524T121401, start_date=20240524T121402, end_date=20240524T121402
[2024-05-24T12:14:02.253+0000] {standard_task_runner.py:110} ERROR - Failed to execute job 717 for task train_model (Training script failed: python: can't open file '/opt/***/../train_model.py': [Errno 2] No such file or directory
; 60)
[2024-05-24T12:14:02.266+0000] {local_task_job_runner.py:240} INFO - Task exited with return code 1
[2024-05-24T12:14:02.275+0000] {taskinstance.py:3498} INFO - 0 downstream tasks scheduled from follow-on schedule check
[2024-05-24T12:14:02.276+0000] {local_task_job_runner.py:222} INFO - ::endgroup::
