[2024-05-24T12:27:30.921+0000] {local_task_job_runner.py:120} INFO - ::group::Pre task execution logs
[2024-05-24T12:27:30.929+0000] {taskinstance.py:2076} INFO - Dependencies all met for dep_context=non-requeueable deps ti=<TaskInstance: train_and_deploy_model.train_model manual__2024-05-24T12:16:45.504364+00:00 [queued]>
[2024-05-24T12:27:30.932+0000] {taskinstance.py:2076} INFO - Dependencies all met for dep_context=requeueable deps ti=<TaskInstance: train_and_deploy_model.train_model manual__2024-05-24T12:16:45.504364+00:00 [queued]>
[2024-05-24T12:27:30.933+0000] {taskinstance.py:2306} INFO - Starting attempt 2 of 2
[2024-05-24T12:27:30.938+0000] {taskinstance.py:2330} INFO - Executing <Task(PythonOperator): train_model> on 2024-05-24 12:16:45.504364+00:00
[2024-05-24T12:27:30.940+0000] {warnings.py:110} WARNING - /home/***/.local/lib/python3.12/site-packages/***/task/task_runner/standard_task_runner.py:61: DeprecationWarning: This process (pid=52) is multi-threaded, use of fork() may lead to deadlocks in the child.
  pid = os.fork()

[2024-05-24T12:27:30.940+0000] {standard_task_runner.py:63} INFO - Started process 53 to run task
[2024-05-24T12:27:30.941+0000] {standard_task_runner.py:90} INFO - Running: ['***', 'tasks', 'run', 'train_and_deploy_model', 'train_model', 'manual__2024-05-24T12:16:45.504364+00:00', '--job-id', '723', '--raw', '--subdir', 'DAGS_FOLDER/train_and_deploy_dag.py', '--cfg-path', '/tmp/tmp9c6qjglz']
[2024-05-24T12:27:30.941+0000] {standard_task_runner.py:91} INFO - Job 723: Subtask train_model
[2024-05-24T12:27:30.958+0000] {task_command.py:426} INFO - Running <TaskInstance: train_and_deploy_model.train_model manual__2024-05-24T12:16:45.504364+00:00 [running]> on host 05665e31ddb1
[2024-05-24T12:27:30.986+0000] {taskinstance.py:2648} INFO - Exporting env vars: AIRFLOW_CTX_DAG_OWNER='***' AIRFLOW_CTX_DAG_ID='train_and_deploy_model' AIRFLOW_CTX_TASK_ID='train_model' AIRFLOW_CTX_EXECUTION_DATE='2024-05-24T12:16:45.504364+00:00' AIRFLOW_CTX_TRY_NUMBER='2' AIRFLOW_CTX_DAG_RUN_ID='manual__2024-05-24T12:16:45.504364+00:00'
[2024-05-24T12:27:30.986+0000] {taskinstance.py:430} INFO - ::endgroup::
[2024-05-24T12:27:31.827+0000] {taskinstance.py:441} INFO - ::group::Post task execution logs
[2024-05-24T12:27:31.828+0000] {taskinstance.py:2905} ERROR - Task failed with exception
Traceback (most recent call last):
  File "/home/airflow/.local/lib/python3.12/site-packages/airflow/models/taskinstance.py", line 465, in _execute_task
    result = _execute_callable(context=context, **execute_callable_kwargs)
             ^^^^^^^^^^^^^^^^^^^^^^^^^^^^^^^^^^^^^^^^^^^^^^^^^^^^^^^^^^^^^
  File "/home/airflow/.local/lib/python3.12/site-packages/airflow/models/taskinstance.py", line 432, in _execute_callable
    return execute_callable(context=context, **execute_callable_kwargs)
           ^^^^^^^^^^^^^^^^^^^^^^^^^^^^^^^^^^^^^^^^^^^^^^^^^^^^^^^^^^^^
  File "/home/airflow/.local/lib/python3.12/site-packages/airflow/models/baseoperator.py", line 400, in wrapper
    return func(self, *args, **kwargs)
           ^^^^^^^^^^^^^^^^^^^^^^^^^^^
  File "/home/airflow/.local/lib/python3.12/site-packages/airflow/operators/python.py", line 235, in execute
    return_value = self.execute_callable()
                   ^^^^^^^^^^^^^^^^^^^^^^^
  File "/home/airflow/.local/lib/python3.12/site-packages/airflow/operators/python.py", line 252, in execute_callable
    return self.python_callable(*self.op_args, **self.op_kwargs)
           ^^^^^^^^^^^^^^^^^^^^^^^^^^^^^^^^^^^^^^^^^^^^^^^^^^^^^
  File "/opt/airflow/dags/train_and_deploy_dag.py", line 26, in train_model
    raise Exception(f"Training script failed: {result.stderr}")
Exception: Training script failed: Traceback (most recent call last):
  File "/scripts/train_model.py", line 2, in <module>
    from surprise import Dataset, Reader, SVD, accuracy
ModuleNotFoundError: No module named 'surprise'

[2024-05-24T12:27:31.833+0000] {taskinstance.py:1206} INFO - Marking task as FAILED. dag_id=train_and_deploy_model, task_id=train_model, run_id=manual__2024-05-24T12:16:45.504364+00:00, execution_date=20240524T121645, start_date=20240524T122730, end_date=20240524T122731
[2024-05-24T12:27:31.838+0000] {standard_task_runner.py:110} ERROR - Failed to execute job 723 for task train_model (Training script failed: Traceback (most recent call last):
  File "/scripts/train_model.py", line 2, in <module>
    from surprise import Dataset, Reader, SVD, accuracy
ModuleNotFoundError: No module named 'surprise'
; 53)
[2024-05-24T12:27:31.874+0000] {local_task_job_runner.py:240} INFO - Task exited with return code 1
[2024-05-24T12:27:31.883+0000] {taskinstance.py:3498} INFO - 0 downstream tasks scheduled from follow-on schedule check
[2024-05-24T12:27:31.885+0000] {local_task_job_runner.py:222} INFO - ::endgroup::
