[2024-05-24T11:48:02.927+0000] {local_task_job_runner.py:120} INFO - ::group::Pre task execution logs
[2024-05-24T11:48:02.970+0000] {taskinstance.py:2076} INFO - Dependencies all met for dep_context=non-requeueable deps ti=<TaskInstance: train_and_deploy_model.manage_models manual__2024-05-24T11:26:26.955364+00:00 [queued]>
[2024-05-24T11:48:02.987+0000] {taskinstance.py:2076} INFO - Dependencies all met for dep_context=requeueable deps ti=<TaskInstance: train_and_deploy_model.manage_models manual__2024-05-24T11:26:26.955364+00:00 [queued]>
[2024-05-24T11:48:02.989+0000] {taskinstance.py:2306} INFO - Starting attempt 2 of 2
[2024-05-24T11:48:03.011+0000] {taskinstance.py:2330} INFO - Executing <Task(PythonOperator): manage_models> on 2024-05-24 11:26:26.955364+00:00
[2024-05-24T11:48:03.023+0000] {warnings.py:110} WARNING - /home/***/.local/lib/python3.12/site-packages/***/task/task_runner/standard_task_runner.py:61: DeprecationWarning: This process (pid=60) is multi-threaded, use of fork() may lead to deadlocks in the child.
  pid = os.fork()

[2024-05-24T11:48:03.030+0000] {standard_task_runner.py:63} INFO - Started process 68 to run task
[2024-05-24T11:48:03.028+0000] {standard_task_runner.py:90} INFO - Running: ['***', 'tasks', 'run', 'train_and_deploy_model', 'manage_models', 'manual__2024-05-24T11:26:26.955364+00:00', '--job-id', '127', '--raw', '--subdir', 'DAGS_FOLDER/train_and_deploy_dag.py', '--cfg-path', '/tmp/tmp3awzhd_b']
[2024-05-24T11:48:03.034+0000] {standard_task_runner.py:91} INFO - Job 127: Subtask manage_models
[2024-05-24T11:48:03.087+0000] {task_command.py:426} INFO - Running <TaskInstance: train_and_deploy_model.manage_models manual__2024-05-24T11:26:26.955364+00:00 [running]> on host b2ab95bd73fd
[2024-05-24T11:48:03.156+0000] {taskinstance.py:2648} INFO - Exporting env vars: AIRFLOW_CTX_DAG_OWNER='***' AIRFLOW_CTX_DAG_ID='train_and_deploy_model' AIRFLOW_CTX_TASK_ID='manage_models' AIRFLOW_CTX_EXECUTION_DATE='2024-05-24T11:26:26.955364+00:00' AIRFLOW_CTX_TRY_NUMBER='2' AIRFLOW_CTX_DAG_RUN_ID='manual__2024-05-24T11:26:26.955364+00:00'
[2024-05-24T11:48:03.160+0000] {taskinstance.py:430} INFO - ::endgroup::
[2024-05-24T11:48:03.185+0000] {taskinstance.py:441} INFO - ::group::Post task execution logs
[2024-05-24T11:48:03.187+0000] {taskinstance.py:2905} ERROR - Task failed with exception
Traceback (most recent call last):
  File "/home/airflow/.local/lib/python3.12/site-packages/airflow/models/taskinstance.py", line 465, in _execute_task
    result = _execute_callable(context=context, **execute_callable_kwargs)
             ^^^^^^^^^^^^^^^^^^^^^^^^^^^^^^^^^^^^^^^^^^^^^^^^^^^^^^^^^^^^^
  File "/home/airflow/.local/lib/python3.12/site-packages/airflow/models/taskinstance.py", line 432, in _execute_callable
    return execute_callable(context=context, **execute_callable_kwargs)
           ^^^^^^^^^^^^^^^^^^^^^^^^^^^^^^^^^^^^^^^^^^^^^^^^^^^^^^^^^^^^
  File "/home/airflow/.local/lib/python3.12/site-packages/airflow/models/baseoperator.py", line 400, in wrapper
    return func(self, *args, **kwargs)
           ^^^^^^^^^^^^^^^^^^^^^^^^^^^
  File "/home/airflow/.local/lib/python3.12/site-packages/airflow/operators/python.py", line 235, in execute
    return_value = self.execute_callable()
                   ^^^^^^^^^^^^^^^^^^^^^^^
  File "/home/airflow/.local/lib/python3.12/site-packages/airflow/operators/python.py", line 252, in execute_callable
    return self.python_callable(*self.op_args, **self.op_kwargs)
           ^^^^^^^^^^^^^^^^^^^^^^^^^^^^^^^^^^^^^^^^^^^^^^^^^^^^^
  File "/opt/airflow/dags/train_and_deploy_dag.py", line 32, in manage_models
    all_models = sorted(os.listdir(models_path), reverse=True)
                        ^^^^^^^^^^^^^^^^^^^^^^^
FileNotFoundError: [Errno 2] No such file or directory: 'models'
[2024-05-24T11:48:03.212+0000] {taskinstance.py:1206} INFO - Marking task as FAILED. dag_id=train_and_deploy_model, task_id=manage_models, run_id=manual__2024-05-24T11:26:26.955364+00:00, execution_date=20240524T112626, start_date=20240524T114802, end_date=20240524T114803
[2024-05-24T11:48:03.232+0000] {standard_task_runner.py:110} ERROR - Failed to execute job 127 for task manage_models ([Errno 2] No such file or directory: 'models'; 68)
[2024-05-24T11:48:03.258+0000] {local_task_job_runner.py:240} INFO - Task exited with return code 1
[2024-05-24T11:48:03.298+0000] {taskinstance.py:3498} INFO - 0 downstream tasks scheduled from follow-on schedule check
[2024-05-24T11:48:03.309+0000] {local_task_job_runner.py:222} INFO - ::endgroup::
