[2024-05-24T12:01:01.500+0000] {local_task_job_runner.py:120} INFO - ::group::Pre task execution logs
[2024-05-24T12:01:01.510+0000] {taskinstance.py:2076} INFO - Dependencies all met for dep_context=non-requeueable deps ti=<TaskInstance: train_and_deploy_model.manage_models manual__2024-05-24T12:01:00.298981+00:00 [queued]>
[2024-05-24T12:01:01.514+0000] {taskinstance.py:2076} INFO - Dependencies all met for dep_context=requeueable deps ti=<TaskInstance: train_and_deploy_model.manage_models manual__2024-05-24T12:01:00.298981+00:00 [queued]>
[2024-05-24T12:01:01.514+0000] {taskinstance.py:2306} INFO - Starting attempt 1 of 2
[2024-05-24T12:01:01.521+0000] {taskinstance.py:2330} INFO - Executing <Task(PythonOperator): manage_models> on 2024-05-24 12:01:00.298981+00:00
[2024-05-24T12:01:01.525+0000] {warnings.py:110} WARNING - /home/***/.local/lib/python3.12/site-packages/***/task/task_runner/standard_task_runner.py:61: DeprecationWarning: This process (pid=623) is multi-threaded, use of fork() may lead to deadlocks in the child.
  pid = os.fork()

[2024-05-24T12:01:01.526+0000] {standard_task_runner.py:63} INFO - Started process 629 to run task
[2024-05-24T12:01:01.526+0000] {standard_task_runner.py:90} INFO - Running: ['***', 'tasks', 'run', 'train_and_deploy_model', 'manage_models', 'manual__2024-05-24T12:01:00.298981+00:00', '--job-id', '456', '--raw', '--subdir', 'DAGS_FOLDER/train_and_deploy_dag.py', '--cfg-path', '/tmp/tmp_k13yuvt']
[2024-05-24T12:01:01.527+0000] {standard_task_runner.py:91} INFO - Job 456: Subtask manage_models
[2024-05-24T12:01:01.547+0000] {task_command.py:426} INFO - Running <TaskInstance: train_and_deploy_model.manage_models manual__2024-05-24T12:01:00.298981+00:00 [running]> on host b2ab95bd73fd
[2024-05-24T12:01:01.579+0000] {taskinstance.py:2648} INFO - Exporting env vars: AIRFLOW_CTX_DAG_OWNER='***' AIRFLOW_CTX_DAG_ID='train_and_deploy_model' AIRFLOW_CTX_TASK_ID='manage_models' AIRFLOW_CTX_EXECUTION_DATE='2024-05-24T12:01:00.298981+00:00' AIRFLOW_CTX_TRY_NUMBER='1' AIRFLOW_CTX_DAG_RUN_ID='manual__2024-05-24T12:01:00.298981+00:00'
[2024-05-24T12:01:01.580+0000] {taskinstance.py:430} INFO - ::endgroup::
[2024-05-24T12:01:01.585+0000] {taskinstance.py:441} INFO - ::group::Post task execution logs
[2024-05-24T12:01:01.586+0000] {taskinstance.py:2905} ERROR - Task failed with exception
Traceback (most recent call last):
  File "/home/airflow/.local/lib/python3.12/site-packages/airflow/models/taskinstance.py", line 465, in _execute_task
    result = _execute_callable(context=context, **execute_callable_kwargs)
             ^^^^^^^^^^^^^^^^^^^^^^^^^^^^^^^^^^^^^^^^^^^^^^^^^^^^^^^^^^^^^
  File "/home/airflow/.local/lib/python3.12/site-packages/airflow/models/taskinstance.py", line 432, in _execute_callable
    return execute_callable(context=context, **execute_callable_kwargs)
           ^^^^^^^^^^^^^^^^^^^^^^^^^^^^^^^^^^^^^^^^^^^^^^^^^^^^^^^^^^^^
  File "/home/airflow/.local/lib/python3.12/site-packages/airflow/models/baseoperator.py", line 400, in wrapper
    return func(self, *args, **kwargs)
           ^^^^^^^^^^^^^^^^^^^^^^^^^^^
  File "/home/airflow/.local/lib/python3.12/site-packages/airflow/operators/python.py", line 235, in execute
    return_value = self.execute_callable()
                   ^^^^^^^^^^^^^^^^^^^^^^^
  File "/home/airflow/.local/lib/python3.12/site-packages/airflow/operators/python.py", line 252, in execute_callable
    return self.python_callable(*self.op_args, **self.op_kwargs)
           ^^^^^^^^^^^^^^^^^^^^^^^^^^^^^^^^^^^^^^^^^^^^^^^^^^^^^
  File "/opt/airflow/dags/train_and_deploy_dag.py", line 32, in manage_models
    all_models = sorted(os.listdir(models_path), reverse=True)
                        ^^^^^^^^^^^^^^^^^^^^^^^
FileNotFoundError: [Errno 2] No such file or directory: 'models'
[2024-05-24T12:01:01.590+0000] {taskinstance.py:1206} INFO - Marking task as UP_FOR_RETRY. dag_id=train_and_deploy_model, task_id=manage_models, run_id=manual__2024-05-24T12:01:00.298981+00:00, execution_date=20240524T120100, start_date=20240524T120101, end_date=20240524T120101
[2024-05-24T12:01:01.596+0000] {standard_task_runner.py:110} ERROR - Failed to execute job 456 for task manage_models ([Errno 2] No such file or directory: 'models'; 629)
[2024-05-24T12:01:01.623+0000] {local_task_job_runner.py:240} INFO - Task exited with return code 1
[2024-05-24T12:01:01.629+0000] {local_task_job_runner.py:222} INFO - ::endgroup::
